Workbook
Name NearKeyWalls: Dashboard!$N$17

Sheet Universe
A1: Ticker | B1: Tier
A2: IWM | B2: 1
A3: SPY | B3: 1
A4: QQQ | B4: 1
A5: NFLX | B5: 1
A6: AMZN | B6: 1
A7: AAPL | B7: 1
A8: TSLA | B8: 1
A9: META | B9: 1
A10: PLTR | B10: 2
A11: GOOG | B11: 1
A12: MSFT | B12: 1
A13: NVDA | B13: 1
... A61: XLK | B61: 1

Sheet RawData
A1: Ticker | B1: Tier | C1: Date | D1: Price | E1: CallWallStrike | F1: PutWallStrike | G1: FlipStrike | H1: NetGamma | I1: NetVanna | J1: NetCharm | K1: NetDelta | L1: Iv | M1: IvLow | N1: IvHigh | O1: IvRank | P1: Rv | Q1: RvLow | R1: RvHigh | S1: CallVolume | T1: PutVolume | U1: CallOiTotal | V1: PutOiTotal | W1: DominantExpiry | X1: DominantExpiryOi | Y1: DominantExpiryVolume
A2: IWM | B2: 1 | C2: 46164 | E2: 300 | F2: 250 | G2: 85 | H2: -1.1374526e+08 | I2: 19026222 | J2: -2.7872102e+09 | L2: 0.225 | M2: 0.166 | N2: 0.34 | O2: 33.695 | P2: 0.198899 | Q2: 0.125234 | R2: 0.25795 | S2: 674438 | T2: 826894 | U2: 2715615 | V2: 7680662 | W2: 46191 | X2: 2983625 | Y2: 243995
A3: SPY | B3: 1 | C3: 46164 | E3: 800 | F3: 700 | G3: 510 | H3: 5.3889508e+09 | I3: 2.0580981e+08 | J3: 1.2642141e+10 | L3: 0.144 | M3: 0.11 | N3: 0.266 | O3: 21.4149 | P3: 0.102106 | Q3: 0.055588 | R3: 0.201536 | S3: 5261015 | T3: 5024496 | U3: 5772793 | V3: 12998410 | W3: 46191 | X3: 3640387 | Y3: 339177
A4: QQQ | B4: 1 | C4: 46164 | E4: 700 | F4: 600 | G4: 699 | H4: 2.4220886e+09 | I4: 65144054 | J4: 1.4710499e+09 | L4: 0.206 | M4: 0.146 | N4: 0.296 | O4: 39.3858 | P4: 0.165838 | Q4: 0.069146 | R4: 0.237161 | S4: 2802929 | T4: 3003604 | U4: 4116625 | V4: 6835468 | W4: 46191 | X4: 2681909 | Y4: 197874
A5: NFLX | B5: 1 | C5: 46164 | E5: 100 | F5: 5 | G5: 7.5 | H5: 1921749.3 | I5: 487562.39 | J5: -29661942 | L5: 0.291 | M5: 0.244 | N5: 0.494 | O5: 19.2791 | P5: 0.244201 | Q5: 0.150297 | R5: 0.595555 | S5: 206131 | T5: 66367 | U5: 3151311 | V5: 2572503 | W5: 46402 | X5: 1388932 | Y5: 2736
A6: AMZN | B6: 1 | C6: 46164 | E6: 275 | F6: 200 | G6: 75 | H6: 1.0070418e+09 | I6: 32678541 | J6: -1.518976e+13 | L6: 0.285 | M6: 0.232 | N6: 0.503 | O6: 19.6487 | P6: 0.22646 | Q6: 0.153711 | R6: 0.475814 | S6: 441807 | T6: 148390 | U6: 3076888 | V6: 1877472 | W6: 46402 | X6: 984489 | Y6: 11795
A7: AAPL | B7: 1 | C7: 46164 | E7: 300 | F7: 250 | G7: 232.5 | H7: -57126530 | I7: 12376016 | J7: -9.9215026e+08 | L7: 0.215 | M7: 0.17 | N7: 0.343 | O7: 25.7175 | P7: 0.188297 | Q7: 0.095372 | R7: 0.33883 | S7: 1073441 | T7: 563369 | U7: 2876488 | V7: 2044306 | W7: 46191 | X7: 966835 | Y7: 111646
A8: TSLA | B8: 1 | C8: 46164 | E8: 500 | F8: 250 | G8: 125 | H8: 1.2684482e+09 | I8: 29148120 | J8: -3.1070127e+13 | L8: 0.437 | M8: 0.39 | N8: 0.773 | O8: 12.1938 | P8: 0.380321 | Q8: 0.285293 | R8: 0.80359 | S8: 2747097 | T8: 1351064 | U8: 4062569 | V8: 2966658 | W8: 46191 | X8: 1225196 | Y8: 99531
A9: META | B9: 1 | C9: 46164 | E9: 750 | F9: 600 | G9: 15 | H9: -61439.21 | I9: 228221.49 | J9: -1.3392853e+08 | L9: 0.291 | M9: 0.234 | N9: 0.488 | O9: 21.5491 | P9: 0.356578 | Q9: 0.17115 | R9: 0.52789 | S9: 346829 | T9: 135183 | U9: 2087027 | V9: 956923 | W9: 46191 | X9: 760478 | Y9: 27179
A10: PLTR | B10: 2 | C10: 46164 | E10: 150 | F10: 120 | G10: 13 | H10: 4.3617839e+08 | I10: 9821427.6 | J10: -1.4591423e+13 | L10: 0.442 | M10: 0.405 | N10: 0.746 | O10: 10.8507 | P10: 0.379347 | Q10: 0.282077 | R10: 0.729886 | S10: 341790 | T10: 173373 | U10: 1882187 | V10: 1839500 | W10: 46191 | X10: 668072 | Y10: 34274
A11: GOOG | B11: 1 | C11: 46164 | E11: 400 | F11: 330 | G11: 282.5 | H11: -12189792 | I11: 5308760.4 | J11: -4.8734094e+08 | L11: 0.285 | M11: 0.245 | N11: 0.444 | O11: 19.2904 | P11: 0.403004 | Q11: 0.157629 | R11: 0.407673 | S11: 127570 | T11: 69301 | U11: 1041699 | V11: 834193 | W11: 46191 | X11: 424497 | Y11: 25850
A12: MSFT | B12: 1 | C12: 46164 | E12: 575 | F12: 400 | G12: 180 | H12: 8.4453968e+08 | I12: 57157830 | J12: -3.0616997e+13 | L12: 0.269 | M12: 0.164 | N12: 0.406 | O12: 44.4592 | P12: 0.241303 | Q12: 0.099789 | R12: 0.485855 | S12: 562976 | T12: 161293 | U12: 2725119 | V12: 1285293 | W12: 46191 | X12: 740003 | Y12: 54603
A13: NVDA | B13: 1 | C13: 46164 | E13: 200 | F13: 200 | G13: 272.5 | H13: 8.8072658e+08 | I13: 93534755 | J13: -4.3128243e+13 | L13: 0.367 | M13: 0.312 | N13: 0.551 | O13: 27.2617 | P13: 0.444711 | Q13: 0.219718 | R13: 0.46929 | S13: 2937462 | T13: 1381796 | U13: 9335988 | V13: 7335020 | W13: 46191 | X13: 3397169 | Y13: 242949
... A21: PANW | B21: 1 | C21: 46164 | E21: 200 | F21: 150 | G21: 30 | H21: 45915726 | I21: 1860260.5 | J21: -4.3438051e+11 | L21: 0.581 | M21: 0.251 | N21: 0.601 | O21: 95.8309 | P21: 0.38541 | Q21: 0.145155 | R21: 0.556262 | S21: 26423 | T21: 20968 | U21: 285582 | V21: 298390 | W21: 46191 | X21: 138339 | Y21: 5295
A22: ORCL | B22: 1 | E22: 200 | F22: 150 | G22: 132 | H22: 1.4966768e+08 | I22: 11119833 | J22: -9.9141773e+12 | S22: 219215 | T22: 75694 | U22: 1249304 | V22: 1117825 | W22: 46191 | X22: 542398 | Y22: 17652
A23: NET | B23: 1 | C23: 46164 | E23: 250 | F23: 140 | G23: 136 | H23: 11945628 | I23: 1245739.8 | J23: -7.3786946e+10 | L23: 0.583 | M23: 0.387 | N23: 0.887 | O23: 41.7754 | P23: 1.087132 | Q23: 0.26208 | R23: 1.264386 | S23: 6721 | T23: 7562 | U23: 158494 | V23: 117993 | W23: 46191 | X23: 71263 | Y23: 1936
A24: CRWD | B24: 1 | C24: 46164 | E24: 470 | F24: 300 | G24: 352.5 | H24: -3799318.8 | I24: 377993.19 | J24: -1.6872428e+08 | L24: 0.581 | M24: 0.317 | N24: 0.669 | O24: 75.2998 | P24: 0.368607 | Q24: 0.245752 | R24: 0.739051 | S24: 32164 | T24: 26530 | U24: 207043 | V24: 189477 | W24: 46191 | X24: 81348 | Y24: 6686
A25: CRM | B25: 1 | C25: 46164 | E25: 200 | F25: 160 | G25: 129 | H25: 17337627 | I25: 760614.75 | J25: -4.6835643e+12 | L25: 0.546 | M25: 0.237 | N25: 0.605 | O25: 87.8701 | P25: 0.388621 | Q25: 0.173688 | R25: 0.514457 | S25: 38542 | T25: 19601 | U25: 515728 | V25: 399312 | W25: 46191 | X25: 226212 | Y25: 8620
A26: NOW | B26: 1 | C26: 46164 | E26: 100 | F26: 75 | G26: 67 | H26: 52474885 | I26: 4122604.3 | J26: -2.5648191e+12 | L26: 0.558 | M26: 0.271 | N26: 0.748 | O26: 58.9803 | P26: 0.531417 | Q26: 0.143458 | R26: 0.959197 | S26: 161945 | T26: 52814 | U26: 866155 | V26: 613078 | W26: 46191 | X26: 282455 | Y26: 35490
A27: ADBE | B27: 1 | C27: 46164 | E27: 200 | F27: 200 | G27: 192.5 | H27: -44429090 | I27: 1884896.6 | J27: -2.7365687e+12 | L27: 0.521 | M27: 0.226 | N27: 0.578 | O27: 82.3447 | P27: 0.346938 | Q27: 0.183772 | R27: 0.471097 | S27: 25374 | T27: 23348 | U27: 367883 | V27: 252842 | W27: 46191 | X27: 129976 | Y27: 4173
A28: AAOI | B28: 3 | C28: 46164 | E28: 200 | F28: 84 | G28: 1 | H28: 8029966.4 | I28: 1340663.5 | J28: -1.4959266e+12 | L28: 1.264 | M28: 0.858 | N28: 1.629 | O28: 53.3934 | P28: 1.569892 | Q28: 0.563125 | R28: 2.31958 | S28: 46231 | T28: 67168 | U28: 147922 | V28: 174750 | W28: 46164 | X28: 100947 | Y28: 34251
A29: QCOM | B29: 1 | C29: 46164 | E29: 220 | F29: 200 | G29: 111 | H29: -7175843.7 | I29: -1707299 | J29: 2276007 | L29: 0.788 | M29: 0.251 | N29: 0.81 | O29: 96.6571 | P29: 1.023039 | Q29: 0.162462 | R29: 1.023039 | S29: 302897 | T29: 112118 | U29: 636773 | V29: 455738 | W29: 46191 | X29: 255107 | Y29: 69505
A30: MU | B30: 1 | C30: 46164 | E30: 800 | F30: 400 | G30: 255 | H30: -32451823 | I30: 4203905.8 | J30: -4.7701445e+13 | L30: 0.851 | M30: 0.381 | N30: 0.995 | O30: 77.395 | P30: 0.862008 | Q30: 0.280712 | R30: 0.890681 | S30: 524198 | T30: 480517 | U30: 1522249 | V30: 1834576 | W30: 46191 | X30: 667028 | Y30: 38197
A31: TSM | B31: 1 | C31: 46164 | E31: 400 | F31: 400 | G31: 105 | H31: 80069109 | I31: 6635813.8 | J31: -1.1501478e+13 | L31: 0.417 | M31: 0.29 | N31: 0.508 | O31: 58.4984 | P31: 0.402368 | Q31: 0.215963 | R31: 0.503352 | S31: 53079 | T31: 79112 | U31: 810353 | V31: 1004251 | W31: 46191 | X31: 371773 | Y31: 10578
A32: AMAT | B32: 2 | C32: 46164 | E32: 490 | F32: 300 | G32: 302.5 | H32: -1823574.3 | I32: 235286.85 | J32: -4.220796e+10 | L32: 0.544 | M32: 0.28 | N32: 0.675 | O32: 66.6835 | P32: 0.538733 | Q32: 0.221634 | R32: 0.600546 | S32: 22721 | T32: 24607 | U32: 188024 | V32: 185580 | W32: 46191 | X32: 88592 | Y32: 6103
A33: AMD | B33: 1 | C33: 46164 | E33: 400 | F33: 200 | G33: 217.5 | H33: -13965362 | I33: -4909822.6 | J33: 3.4864899e+08 | L33: 0.671 | M33: 0.387 | N33: 0.733 | O33: 82.3996 | P33: 0.965858 | Q33: 0.316487 | R33: 0.984808 | S33: 586572 | T33: 304991 | U33: 1598814 | V33: 1709886 | W33: 46191 | X33: 661745 | Y33: 55820
A34: INTC | B34: 2 | C34: 46164 | E34: 50 | F34: 15 | G34: 59 | H34: 3.5111267e+08 | I34: 13882382 | J34: -6.1115445e+12 | L34: 0.787 | M34: 0.382 | N34: 0.965 | O34: 71.2546 | P34: 1.1174 | Q34: 0.338625 | R34: 1.135036 | S34: 477628 | T34: 327384 | U34: 2899377 | V34: 3127750 | W34: 46191 | X34: 1442570 | Y34: 79391
... A41: RIOT | B41: 2 | C41: 46164 | E41: 25 | F41: 15 | G41: 7.5 | H41: 12264559 | I41: 622976.11 | J41: -1.2419652e+12 | L41: 0.788 | M41: 0.666 | N41: 1.122 | O41: 28.2709 | P41: 0.865101 | Q41: 0.522947 | R41: 1.244419 | S41: 55244 | T41: 61117 | U41: 554991 | V41: 285163 | W41: 46191 | X41: 275777 | Y41: 7707
A42: COIN | B42: 2 | C42: 46164 | G42: 15 | H42: -21977639 | I42: 4284208.4 | J42: -2.7572469e+12 | L42: 0.631 | M42: 0.477 | N42: 0.957 | O42: 32.5493 | P42: 0.649939 | Q42: 0.380583 | R42: 1.228315 | S42: 144266 | T42: 64861 | U42: 669555 | V42: 495557 | W42: 46191 | X42: 233196 | Y42: 14435
A43: MSTR | B43: 2 | C43: 46164 | E43: 180 | F43: 5 | G43: 6 | H43: -39853546 | I43: 9839553.7 | J43: -8.2725024e+12 | L43: 0.611 | M43: 0.436 | N43: 1.264 | O43: 21.5634 | P43: 0.626217 | Q43: 0.324639 | R43: 1.310859 | S43: 288402 | T43: 153961 | U43: 1388885 | V43: 1264846 | W43: 46191 | X43: 695133 | Y43: 30462
A44: SNOW | B44: 2 | C44: 46164 | E44: 200 | F44: 140 | G44: 109 | H44: 40439254 | I44: 1260240 | J44: -7.5575632e+10 | L44: 0.808 | M44: 0.304 | N44: 0.875 | O44: 86.7645 | P44: 0.510476 | Q44: 0.195775 | R44: 0.871147 | S44: 42680 | T44: 15765 | U44: 319669 | V44: 259367 | W44: 46191 | X44: 108665 | Y44: 8053
A45: LLY | B45: 2 | C45: 46164 | E45: 1100 | F45: 700 | G45: 350 | H45: 1.2491818e+08 | I45: 4334655 | J45: 5.2488939e+11 | L45: 0.313 | M45: 0.267 | N45: 0.48 | O45: 19.5774 | P45: 0.456137 | Q45: 0.199359 | R45: 0.674942 | S45: 40647 | T45: 15716 | U45: 169732 | V45: 190855 | W45: 46191 | X45: 85906 | Y45: 8027
A46: JNJ | B46: 2 | C46: 46164 | E46: 230 | F46: 210 | G46: 202.5 | H46: 95944289 | I46: 1065685.2 | J46: -1.145073e+12 | L46: 0.205 | M46: 0.123 | N46: 0.293 | O46: 48.7594 | P46: 0.179954 | Q46: 0.096906 | R46: 0.262832 | S46: 81371 | T46: 8380 | U46: 193322 | V46: 160063 | W46: 46191 | X46: 88024 | Y46: 50199
A47: UNH | B47: 2 | C47: 46164 | E47: 400 | F47: 200 | G47: 205 | H47: 1.7176802e+08 | I47: 5715393 | J47: -3.6568496e+12 | L47: 0.264 | M47: 0.246 | N47: 0.545 | O47: 6.3457 | P47: 0.227251 | Q47: 0.205176 | R47: 0.913601 | S47: 40189 | T47: 19860 | U47: 742852 | V47: 498402 | W47: 46191 | X47: 305668 | Y47: 7711
A48: TGT | B48: 2 | C48: 46164 | E48: 130 | F48: 105 | G48: 99 | H48: 24925509 | I48: 1204612.5 | J48: -6.1160967e+11 | L48: 0.322 | M48: 0.284 | N48: 0.535 | O48: 15.5374 | P48: 0.355663 | Q48: 0.167803 | R48: 0.407595 | S48: 23318 | T48: 11141 | U48: 313858 | V48: 258550 | W48: 46402 | X48: 121180 | Y48: 985
A49: HD | B49: 2 | C49: 46164 | E49: 360 | F49: 300 | G49: 155 | H49: 48468681 | I49: 1064182.7 | J49: -1.817217e+12 | L49: 0.288 | M49: 0.175 | N49: 0.353 | O49: 63.8706 | P49: 0.269137 | Q49: 0.097514 | R49: 0.343959 | S49: 19198 | T49: 8684 | U49: 178329 | V49: 130287 | W49: 46191 | X49: 73466 | Y49: 2409
A50: COST | B50: 2 | C50: 46164 | E50: 1100 | F50: 800 | G50: 725 | H50: -10716911 | I50: 3208517.5 | J50: -9.4083386e+11 | L50: 0.257 | M50: 0.173 | N50: 0.298 | O50: 65.4762 | P50: 0.231244 | Q50: 0.104446 | R50: 0.234221 | S50: 18321 | T50: 32751 | U50: 119987 | V50: 167350 | W50: 46164 | X50: 61610 | Y50: 16644
A51: WMT | B51: 2 | C51: 46164 | E51: 135 | F51: 110 | G51: 109 | H51: -1.3523729e+08 | I51: 5158001.4 | J51: -1.6379896e+12 | L51: 0.244 | M51: 0.18 | N51: 0.369 | O51: 31.9369 | P51: 0.337215 | Q51: 0.090487 | R51: 0.347287 | S51: 137226 | T51: 90553 | U51: 517107 | V51: 534719 | W51: 46191 | X51: 255953 | Y51: 30036
A52: MS | B52: 1 | C52: 46164 | E52: 200 | F52: 160 | G52: 162.5 | H52: 42020157 | I52: 1753713.8 | J52: -7.7083539e+11 | L52: 0.28 | M52: 0.212 | N52: 0.446 | O52: 29.4269 | P52: 0.233678 | Q52: 0.142241 | R52: 0.427571 | S52: 10581 | T52: 8231 | U52: 159989 | V52: 225966 | W52: 46191 | X52: 100851 | Y52: 4088
A53: GS | B53: 1 | C53: 46164 | E53: 1000 | F53: 800 | G53: 220 | H53: 3.948739e+08 | I53: 1792350.9 | J53: -2.4936511e+12 | L53: 0.284 | M53: 0.224 | N53: 0.458 | O53: 26.6212 | P53: 0.294998 | Q53: 0.16466 | R53: 0.431992 | S53: 29541 | T53: 16498 | U53: 213806 | V53: 190343 | W53: 46191 | X53: 66915 | Y53: 4657
...

Sheet LogicEngine
A1: Ticker | B1: Tier | C1: TierWeight | D1: GammaRegime | E1: DeltaLean | F1: VannaBias | G1: CharmBias | H1: CallWallFlag | I1: PutWallFlag | J1: FlipFlag | K1: BullScore | L1: BearScore | M1: TradeBias | N1: Conviction | O1: Notes
A2: =RawData!A2 -> IWM | B2: =RawData!B2 -> 1 | C2: =IF(B2=1,10,IF(B2=2,5,0)) -> 10 | D2: =IF(RawData!H2="","", IF(RawData!H2>0,"Long Gamma","Short Gamma") ) -> Short Gamma | E2: =IF(RawData!K2="","", IF(RawData!K2>0,"Dealers Long (Sell Rips)","Dealers Short (Buy Rips)") ) | F2: =IF(OR(RawData!I2="",RawData!O2=""),"", IF(RawData!I2>0, IF(RawData!O2>50,"Downside Pressure","Upside Drift"), IF(RawData!O2>50,"Upside Pressure","Downside Drift") ) ) -> Upside Drift | G2: =IF(RawData!J2="","", IF(RawData!J2<0,"Sell Into Close","Buy Into Close") ) -> Sell Into Close | H2: =IF(RawData!E2="","", IF(ABS(RawData!E2 - RawData!D2)/RawData!D2 < 0.02,"Near Call Wall","") ) -> #DIV/0! | I2: =IF(RawData!F2="","", IF(ABS(RawData!F2 - RawData!D2)/RawData!D2 < 0.02,"Near Put Wall","") ) -> #DIV/0! | J2: =IF(RawData!G2="","", IF(RawData!G2 < RawData!D2,"Below Flip","Above Flip") ) -> Above Flip | K2: =IF(RawData!H2="","", (IF(LE[[#This Row],[GammaRegime]]="Long Gamma",10,0)) + (IF(RawData!K2<0,10,0)) + (IF(AND(RawData!I2<0,RawData!O2>50),10,0)) + (IF(AND(RawData!I2>0,RawData!O2<50),10,0)) + (IF(ABS(RawData!E2 - RawData!D2)/RawData!D2 < 0.02,5,0)) + (IF(RawData!G2>RawData!D2,5,0)) + LE[[#This Row],[TierWeight]] ) -> #DIV/0! | L2: =IF(RawData!H2="","", (IF(LE[[#This Row],[GammaRegime]]="Short Gamma",10,0)) + (IF(RawData!K2>0,10,0)) + (IF(AND(RawData!I2>0,RawData!O2>50),10,0)) + (IF(AND(RawData!I2<0,RawData!O2<50),10,0)) + (IF(ABS(RawData!F2 - RawData!D2)/RawData!D2 < 0.02,5,0)) + (IF(RawData!G2<RawData!D2,5,0)) + LE[[#This Row],[TierWeight]] ) -> #DIV/0! | M2: =IF(LE[[#This Row],[BullScore]]>LE[[#This Row],[BearScore]],"Call", IF(LE[[#This Row],[BearScore]]>LE[[#This Row],[BullScore]],"Put","Avoid") ) -> #DIV/0! | N2: =MAX(LE[[#This Row],[BullScore]],LE[[#This Row],[BearScore]]) -> #DIV/0! | O2: =IF(LE[[#This Row],[GammaRegime]]="","", "Bias: " & LE[[#This Row],[TradeBias]] & " | Regime: " & LE[[#This Row],[GammaRegime]] & " | Delta: " & LE[[#This Row],[DeltaLean]] & " | Vanna: " & LE[[#This Row],[VannaBias]] & " | Charm: " & LE[[#This Row],[CharmBias]] & " | Flip: " & LE[[#This Row],[FlipFlag]] ) -> #DIV/0!
A3: =RawData!A3 -> SPY | B3: =RawData!B3 -> 1 | C3: =IF(B3=1,10,IF(B3=2,5,0)) -> 10 | D3: =IF(RawData!H3="","", IF(RawData!H3>0,"Long Gamma","Short Gamma") ) -> Long Gamma | E3: =IF(RawData!K3="","", IF(RawData!K3>0,"Dealers Long (Sell Rips)","Dealers Short (Buy Rips)") ) | F3: =IF(OR(RawData!I3="",RawData!O3=""),"", IF(RawData!I3>0, IF(RawData!O3>50,"Downside Pressure","Upside Drift"), IF(RawData!O3>50,"Upside Pressure","Downside Drift") ) ) -> Upside Drift | G3: =IF(RawData!J3="","", IF(RawData!J3<0,"Sell Into Close","Buy Into Close") ) -> Buy Into Close | H3: =IF(RawData!E3="","", IF(ABS(RawData!E3 - RawData!D3)/RawData!D3 < 0.02,"Near Call Wall","") ) -> #DIV/0! | I3: =IF(RawData!F3="","", IF(ABS(RawData!F3 - RawData!D3)/RawData!D3 < 0.02,"Near Put Wall","") ) -> #DIV/0! | J3: =IF(RawData!G3="","", IF(RawData!G3 < RawData!D3,"Below Flip","Above Flip") ) -> Above Flip | K3: =IF(RawData!H3="","", (IF(LE[[#This Row],[GammaRegime]]="Long Gamma",10,0)) + (IF(RawData!K3<0,10,0)) + (IF(AND(RawData!I3<0,RawData!O3>50),10,0)) + (IF(AND(RawData!I3>0,RawData!O3<50),10,0)) + (IF(ABS(RawData!E3 - RawData!D3)/RawData!D3 < 0.02,5,0)) + (IF(RawData!G3>RawData!D3,5,0)) + LE[[#This Row],[TierWeight]] ) -> #DIV/0! | L3: =IF(RawData!H3="","", (IF(LE[[#This Row],[GammaRegime]]="Short Gamma",10,0)) + (IF(RawData!K3>0,10,0)) + (IF(AND(RawData!I3>0,RawData!O3>50),10,0)) + (IF(AND(RawData!I3<0,RawData!O3<50),10,0)) + (IF(ABS(RawData!F3 - RawData!D3)/RawData!D3 < 0.02,5,0)) + (IF(RawData!G3<RawData!D3,5,0)) + LE[[#This Row],[TierWeight]] ) -> #DIV/0! | M3: =IF(LE[[#This Row],[BullScore]]>LE[[#This Row],[BearScore]],"Call", IF(LE[[#This Row],[BearScore]]>LE[[#This Row],[BullScore]],"Put","Avoid") ) -> #DIV/0! | N3: =MAX(LE[[#This Row],[BullScore]],LE[[#This Row],[BearScore]]) -> #DIV/0! | O3: =IF(LE[[#This Row],[GammaRegime]]="","", "Bias: " & LE[[#This Row],[TradeBias]] & " | Regime: " & LE[[#This Row],[GammaRegime]] & " | Delta: " & LE[[#This Row],[DeltaLean]] & " | Vanna: " & LE[[#This Row],[VannaBias]] & " | Charm: " & LE[[#This Row],[CharmBias]] & " | Flip: " & LE[[#This Row],[FlipFlag]] ) -> #DIV/0!
A4: =RawData!A4 -> QQQ | B4: =RawData!B4 -> 1 | C4: =IF(B4=1,10,IF(B4=2,5,0)) -> 10 | D4: =IF(RawData!H4="","", IF(RawData!H4>0,"Long Gamma","Short Gamma") ) -> Long Gamma | E4: =IF(RawData!K4="","", IF(RawData!K4>0,"Dealers Long (Sell Rips)","Dealers Short (Buy Rips)") ) | F4: =IF(OR(RawData!I4="",RawData!O4=""),"", IF(RawData!I4>0, IF(RawData!O4>50,"Downside Pressure","Upside Drift"), IF(RawData!O4>50,"Upside Pressure","Downside Drift") ) ) -> Upside Drift | G4: =IF(RawData!J4="","", IF(RawData!J4<0,"Sell Into Close","Buy Into Close") ) -> Buy Into Close | H4: =IF(RawData!E4="","", IF(ABS(RawData!E4 - RawData!D4)/RawData!D4 < 0.02,"Near Call Wall","") ) -> #DIV/0! | I4: =IF(RawData!F4="","", IF(ABS(RawData!F4 - RawData!D4)/RawData!D4 < 0.02,"Near Put Wall","") ) -> #DIV/0! | J4: =IF(RawData!G4="","", IF(RawData!G4 < RawData!D4,"Below Flip","Above Flip") ) -> Above Flip | K4: =IF(RawData!H4="","", (IF(LE[[#This Row],[GammaRegime]]="Long Gamma",10,0)) + (IF(RawData!K4<0,10,0)) + (IF(AND(RawData!I4<0,RawData!O4>50),10,0)) + (IF(AND(RawData!I4>0,RawData!O4<50),10,0)) + (IF(ABS(RawData!E4 - RawData!D4)/RawData!D4 < 0.02,5,0)) + (IF(RawData!G4>RawData!D4,5,0)) + LE[[#This Row],[TierWeight]] ) -> #DIV/0! | L4: =IF(RawData!H4="","", (IF(LE[[#This Row],[GammaRegime]]="Short Gamma",10,0)) + (IF(RawData!K4>0,10,0)) + (IF(AND(RawData!I4>0,RawData!O4>50),10,0)) + (IF(AND(RawData!I4<0,RawData!O4<50),10,0)) + (IF(ABS(RawData!F4 - RawData!D4)/RawData!D4 < 0.02,5,0)) + (IF(RawData!G4<RawData!D4,5,0)) + LE[[#This Row],[TierWeight]] ) -> #DIV/0! | M4: =IF(LE[[#This Row],[BullScore]]>LE[[#This Row],[BearScore]],"Call", IF(LE[[#This Row],[BearScore]]>LE[[#This Row],[BullScore]],"Put","Avoid") ) -> #DIV/0! | N4: =MAX(LE[[#This Row],[BullScore]],LE[[#This Row],[BearScore]]) -> #DIV/0! | O4: =IF(LE[[#This Row],[GammaRegime]]="","", "Bias: " & LE[[#This Row],[TradeBias]] & " | Regime: " & LE[[#This Row],[GammaRegime]] & " | Delta: " & LE[[#This Row],[DeltaLean]] & " | Vanna: " & LE[[#This Row],[VannaBias]] & " | Charm: " & LE[[#This Row],[CharmBias]] & " | Flip: " & LE[[#This Row],[FlipFlag]] ) -> #DIV/0!
A5: =RawData!A5 -> NFLX | B5: =RawData!B5 -> 1 | C5: =IF(B5=1,10,IF(B5=2,5,0)) -> 10 | D5: =IF(RawData!H5="","", IF(RawData!H5>0,"Long Gamma","Short Gamma") ) -> Long Gamma | E5: =IF(RawData!K5="","", IF(RawData!K5>0,"Dealers Long (Sell Rips)","Dealers Short (Buy Rips)") ) | F5: =IF(OR(RawData!I5="",RawData!O5=""),"", IF(RawData!I5>0, IF(RawData!O5>50,"Downside Pressure","Upside Drift"), IF(RawData!O5>50,"Upside Pressure","Downside Drift") ) ) -> Upside Drift | G5: =IF(RawData!J5="","", IF(RawData!J5<0,"Sell Into Close","Buy Into Close") ) -> Sell Into Close | H5: =IF(RawData!E5="","", IF(ABS(RawData!E5 - RawData!D5)/RawData!D5 < 0.02,"Near Call Wall","") ) -> #DIV/0! | I5: =IF(RawData!F5="","", IF(ABS(RawData!F5 - RawData!D5)/RawData!D5 < 0.02,"Near Put Wall","") ) -> #DIV/0! | J5: =IF(RawData!G5="","", IF(RawData!G5 < RawData!D5,"Below Flip","Above Flip") ) -> Above Flip | K5: =IF(RawData!H5="","", (IF(LE[[#This Row],[GammaRegime]]="Long Gamma",10,0)) + (IF(RawData!K5<0,10,0)) + (IF(AND(RawData!I5<0,RawData!O5>50),10,0)) + (IF(AND(RawData!I5>0,RawData!O5<50),10,0)) + (IF(ABS(RawData!E5 - RawData!D5)/RawData!D5 < 0.02,5,0)) + (IF(RawData!G5>RawData!D5,5,0)) + LE[[#This Row],[TierWeight]] ) -> #DIV/0! | L5: =IF(RawData!H5="","", (IF(LE[[#This Row],[GammaRegime]]="Short Gamma",10,0)) + (IF(RawData!K5>0,10,0)) + (IF(AND(RawData!I5>0,RawData!O5>50),10,0)) + (IF(AND(RawData!I5<0,RawData!O5<50),10,0)) + (IF(ABS(RawData!F5 - RawData!D5)/RawData!D5 < 0.02,5,0)) + (IF(RawData!G5<RawData!D5,5,0)) + LE[[#This Row],[TierWeight]] ) -> #DIV/0! | M5: =IF(LE[[#This Row],[BullScore]]>LE[[#This Row],[BearScore]],"Call", IF(LE[[#This Row],[BearScore]]>LE[[#This Row],[BullScore]],"Put","Avoid") ) -> #DIV/0! | N5: =MAX(LE[[#This Row],[BullScore]],LE[[#This Row],[BearScore]]) -> #DIV/0! | O5: =IF(LE[[#This Row],[GammaRegime]]="","", "Bias: " & LE[[#This Row],[TradeBias]] & " | Regime: " & LE[[#This Row],[GammaRegime]] & " | Delta: " & LE[[#This Row],[DeltaLean]] & " | Vanna: " & LE[[#This Row],[VannaBias]] & " | Charm: " & LE[[#This Row],[CharmBias]] & " | Flip: " & LE[[#This Row],[FlipFlag]] ) -> #DIV/0!
A6: =RawData!A6 -> AMZN | B6: =RawData!B6 -> 1 | C6: =IF(B6=1,10,IF(B6=2,5,0)) -> 10 | D6: =IF(RawData!H6="","", IF(RawData!H6>0,"Long Gamma","Short Gamma") ) -> Long Gamma | E6: =IF(RawData!K6="","", IF(RawData!K6>0,"Dealers Long (Sell Rips)","Dealers Short (Buy Rips)") ) | F6: =IF(OR(RawData!I6="",RawData!O6=""),"", IF(RawData!I6>0, IF(RawData!O6>50,"Downside Pressure","Upside Drift"), IF(RawData!O6>50,"Upside Pressure","Downside Drift") ) ) -> Upside Drift | G6: =IF(RawData!J6="","", IF(RawData!J6<0,"Sell Into Close","Buy Into Close") ) -> Sell Into Close | H6: =IF(RawData!E6="","", IF(ABS(RawData!E6 - RawData!D6)/RawData!D6 < 0.02,"Near Call Wall","") ) -> #DIV/0! | I6: =IF(RawData!F6="","", IF(ABS(RawData!F6 - RawData!D6)/RawData!D6 < 0.02,"Near Put Wall","") ) -> #DIV/0! | J6: =IF(RawData!G6="","", IF(RawData!G6 < RawData!D6,"Below Flip","Above Flip") ) -> Above Flip | K6: =IF(RawData!H6="","", (IF(LE[[#This Row],[GammaRegime]]="Long Gamma",10,0)) + (IF(RawData!K6<0,10,0)) + (IF(AND(RawData!I6<0,RawData!O6>50),10,0)) + (IF(AND(RawData!I6>0,RawData!O6<50),10,0)) + (IF(ABS(RawData!E6 - RawData!D6)/RawData!D6 < 0.02,5,0)) + (IF(RawData!G6>RawData!D6,5,0)) + LE[[#This Row],[TierWeight]] ) -> #DIV/0! | L6: =IF(RawData!H6="","", (IF(LE[[#This Row],[GammaRegime]]="Short Gamma",10,0)) + (IF(RawData!K6>0,10,0)) + (IF(AND(RawData!I6>0,RawData!O6>50),10,0)) + (IF(AND(RawData!I6<0,RawData!O6<50),10,0)) + (IF(ABS(RawData!F6 - RawData!D6)/RawData!D6 < 0.02,5,0)) + (IF(RawData!G6<RawData!D6,5,0)) + LE[[#This Row],[TierWeight]] ) -> #DIV/0! | M6: =IF(LE[[#This Row],[BullScore]]>LE[[#This Row],[BearScore]],"Call", IF(LE[[#This Row],[BearScore]]>LE[[#This Row],[BullScore]],"Put","Avoid") ) -> #DIV/0! | N6: =MAX(LE[[#This Row],[BullScore]],LE[[#This Row],[BearScore]]) -> #DIV/0! | O6: =IF(LE[[#This Row],[GammaRegime]]="","", "Bias: " & LE[[#This Row],[TradeBias]] & " | Regime: " & LE[[#This Row],[GammaRegime]] & " | Delta: " & LE[[#This Row],[DeltaLean]] & " | Vanna: " & LE[[#This Row],[VannaBias]] & " | Charm: " & LE[[#This Row],[CharmBias]] & " | Flip: " & LE[[#This Row],[FlipFlag]] ) -> #DIV/0!
A7: =RawData!A7 -> AAPL | B7: =RawData!B7 -> 1 | C7: =IF(B7=1,10,IF(B7=2,5,0)) -> 10 | D7: =IF(RawData!H7="","", IF(RawData!H7>0,"Long Gamma","Short Gamma") ) -> Short Gamma | E7: =IF(RawData!K7="","", IF(RawData!K7>0,"Dealers Long (Sell Rips)","Dealers Short (Buy Rips)") ) | F7: =IF(OR(RawData!I7="",RawData!O7=""),"", IF(RawData!I7>0, IF(RawData!O7>50,"Downside Pressure","Upside Drift"), IF(RawData!O7>50,"Upside Pressure","Downside Drift") ) ) -> Upside Drift | G7: =IF(RawData!J7="","", IF(RawData!J7<0,"Sell Into Close","Buy Into Close") ) -> Sell Into Close | H7: =IF(RawData!E7="","", IF(ABS(RawData!E7 - RawData!D7)/RawData!D7 < 0.02,"Near Call Wall","") ) -> #DIV/0! | I7: =IF(RawData!F7="","", IF(ABS(RawData!F7 - RawData!D7)/RawData!D7 < 0.02,"Near Put Wall","") ) -> #DIV/0! | J7: =IF(RawData!G7="","", IF(RawData!G7 < RawData!D7,"Below Flip","Above Flip") ) -> Above Flip | K7: =IF(RawData!H7="","", (IF(LE[[#This Row],[GammaRegime]]="Long Gamma",10,0)) + (IF(RawData!K7<0,10,0)) + (IF(AND(RawData!I7<0,RawData!O7>50),10,0)) + (IF(AND(RawData!I7>0,RawData!O7<50),10,0)) + (IF(ABS(RawData!E7 - RawData!D7)/RawData!D7 < 0.02,5,0)) + (IF(RawData!G7>RawData!D7,5,0)) + LE[[#This Row],[TierWeight]] ) -> #DIV/0! | L7: =IF(RawData!H7="","", (IF(LE[[#This Row],[GammaRegime]]="Short Gamma",10,0)) + (IF(RawData!K7>0,10,0)) + (IF(AND(RawData!I7>0,RawData!O7>50),10,0)) + (IF(AND(RawData!I7<0,RawData!O7<50),10,0)) + (IF(ABS(RawData!F7 - RawData!D7)/RawData!D7 < 0.02,5,0)) + (IF(RawData!G7<RawData!D7,5,0)) + LE[[#This Row],[TierWeight]] ) -> #DIV/0! | M7: =IF(LE[[#This Row],[BullScore]]>LE[[#This Row],[BearScore]],"Call", IF(LE[[#This Row],[BearScore]]>LE[[#This Row],[BullScore]],"Put","Avoid") ) -> #DIV/0! | N7: =MAX(LE[[#This Row],[BullScore]],LE[[#This Row],[BearScore]]) -> #DIV/0! | O7: =IF(LE[[#This Row],[GammaRegime]]="","", "Bias: " & LE[[#This Row],[TradeBias]] & " | Regime: " & LE[[#This Row],[GammaRegime]] & " | Delta: " & LE[[#This Row],[DeltaLean]] & " | Vanna: " & LE[[#This Row],[VannaBias]] & " | Charm: " & LE[[#This Row],[CharmBias]] & " | Flip: " & LE[[#This Row],[FlipFlag]] ) -> #DIV/0!
A8: =RawData!A8 -> TSLA | B8: =RawData!B8 -> 1 | C8: =IF(B8=1,10,IF(B8=2,5,0)) -> 10 | D8: =IF(RawData!H8="","", IF(RawData!H8>0,"Long Gamma","Short Gamma") ) -> Long Gamma | E8: =IF(RawData!K8="","", IF(RawData!K8>0,"Dealers Long (Sell Rips)","Dealers Short (Buy Rips)") ) | F8: =IF(OR(RawData!I8="",RawData!O8=""),"", IF(RawData!I8>0, IF(RawData!O8>50,"Downside Pressure","Upside Drift"), IF(RawData!O8>50,"Upside Pressure","Downside Drift") ) ) -> Upside Drift | G8: =IF(RawData!J8="","", IF(RawData!J8<0,"Sell Into Close","Buy Into Close") ) -> Sell Into Close | H8: =IF(RawData!E8="","", IF(ABS(RawData!E8 - RawData!D8)/RawData!D8 < 0.02,"Near Call Wall","") ) -> #DIV/0! | I8: =IF(RawData!F8="","", IF(ABS(RawData!F8 - RawData!D8)/RawData!D8 < 0.02,"Near Put Wall","") ) -> #DIV/0! | J8: =IF(RawData!G8="","", IF(RawData!G8 < RawData!D8,"Below Flip","Above Flip") ) -> Above Flip | K8: =IF(RawData!H8="","", (IF(LE[[#This Row],[GammaRegime]]="Long Gamma",10,0)) + (IF(RawData!K8<0,10,0)) + (IF(AND(RawData!I8<0,RawData!O8>50),10,0)) + (IF(AND(RawData!I8>0,RawData!O8<50),10,0)) + (IF(ABS(RawData!E8 - RawData!D8)/RawData!D8 < 0.02,5,0)) + (IF(RawData!G8>RawData!D8,5,0)) + LE[[#This Row],[TierWeight]] ) -> #DIV/0! | L8: =IF(RawData!H8="","", (IF(LE[[#This Row],[GammaRegime]]="Short Gamma",10,0)) + (IF(RawData!K8>0,10,0)) + (IF(AND(RawData!I8>0,RawData!O8>50),10,0)) + (IF(AND(RawData!I8<0,RawData!O8<50),10,0)) + (IF(ABS(RawData!F8 - RawData!D8)/RawData!D8 < 0.02,5,0)) + (IF(RawData!G8<RawData!D8,5,0)) + LE[[#This Row],[TierWeight]] ) -> #DIV/0! | M8: =IF(LE[[#This Row],[BullScore]]>LE[[#This Row],[BearScore]],"Call", IF(LE[[#This Row],[BearScore]]>LE[[#This Row],[BullScore]],"Put","Avoid") ) -> #DIV/0! | N8: =MAX(LE[[#This Row],[BullScore]],LE[[#This Row],[BearScore]]) -> #DIV/0! | O8: =IF(LE[[#This Row],[GammaRegime]]="","", "Bias: " & LE[[#This Row],[TradeBias]] & " | Regime: " & LE[[#This Row],[GammaRegime]] & " | Delta: " & LE[[#This Row],[DeltaLean]] & " | Vanna: " & LE[[#This Row],[VannaBias]] & " | Charm: " & LE[[#This Row],[CharmBias]] & " | Flip: " & LE[[#This Row],[FlipFlag]] ) -> #DIV/0!
A9: =RawData!A9 -> META | B9: =RawData!B9 -> 1 | C9: =IF(B9=1,10,IF(B9=2,5,0)) -> 10 | D9: =IF(RawData!H9="","", IF(RawData!H9>0,"Long Gamma","Short Gamma") ) -> Short Gamma | E9: =IF(RawData!K9="","", IF(RawData!K9>0,"Dealers Long (Sell Rips)","Dealers Short (Buy Rips)") ) | F9: =IF(OR(RawData!I9="",RawData!O9=""),"", IF(RawData!I9>0, IF(RawData!O9>50,"Downside Pressure","Upside Drift"), IF(RawData!O9>50,"Upside Pressure","Downside Drift") ) ) -> Upside Drift | G9: =IF(RawData!J9="","", IF(RawData!J9<0,"Sell Into Close","Buy Into Close") ) -> Sell Into Close | H9: =IF(RawData!E9="","", IF(ABS(RawData!E9 - RawData!D9)/RawData!D9 < 0.02,"Near Call Wall","") ) -> #DIV/0! | I9: =IF(RawData!F9="","", IF(ABS(RawData!F9 - RawData!D9)/RawData!D9 < 0.02,"Near Put Wall","") ) -> #DIV/0! | J9: =IF(RawData!G9="","", IF(RawData!G9 < RawData!D9,"Below Flip","Above Flip") ) -> Above Flip | K9: =IF(RawData!H9="","", (IF(LE[[#This Row],[GammaRegime]]="Long Gamma",10,0)) + (IF(RawData!K9<0,10,0)) + (IF(AND(RawData!I9<0,RawData!O9>50),10,0)) + (IF(AND(RawData!I9>0,RawData!O9<50),10,0)) + (IF(ABS(RawData!E9 - RawData!D9)/RawData!D9 < 0.02,5,0)) + (IF(RawData!G9>RawData!D9,5,0)) + LE[[#This Row],[TierWeight]] ) -> #DIV/0! | L9: =IF(RawData!H9="","", (IF(LE[[#This Row],[GammaRegime]]="Short Gamma",10,0)) + (IF(RawData!K9>0,10,0)) + (IF(AND(RawData!I9>0,RawData!O9>50),10,0)) + (IF(AND(RawData!I9<0,RawData!O9<50),10,0)) + (IF(ABS(RawData!F9 - RawData!D9)/RawData!D9 < 0.02,5,0)) + (IF(RawData!G9<RawData!D9,5,0)) + LE[[#This Row],[TierWeight]] ) -> #DIV/0! | M9: =IF(LE[[#This Row],[BullScore]]>LE[[#This Row],[BearScore]],"Call", IF(LE[[#This Row],[BearScore]]>LE[[#This Row],[BullScore]],"Put","Avoid") ) -> #DIV/0! | N9: =MAX(LE[[#This Row],[BullScore]],LE[[#This Row],[BearScore]]) -> #DIV/0! | O9: =IF(LE[[#This Row],[GammaRegime]]="","", "Bias: " & LE[[#This Row],[TradeBias]] & " | Regime: " & LE[[#This Row],[GammaRegime]] & " | Delta: " & LE[[#This Row],[DeltaLean]] & " | Vanna: " & LE[[#This Row],[VannaBias]] & " | Charm: " & LE[[#This Row],[CharmBias]] & " | Flip: " & LE[[#This Row],[FlipFlag]] ) -> #DIV/0!
A10: =RawData!A10 -> PLTR | B10: =RawData!B10 -> 2 | C10: =IF(B10=1,10,IF(B10=2,5,0)) -> 5 | D10: =IF(RawData!H10="","", IF(RawData!H10>0,"Long Gamma","Short Gamma") ) -> Long Gamma | E10: =IF(RawData!K10="","", IF(RawData!K10>0,"Dealers Long (Sell Rips)","Dealers Short (Buy Rips)") ) | F10: =IF(OR(RawData!I10="",RawData!O10=""),"", IF(RawData!I10>0, IF(RawData!O10>50,"Downside Pressure","Upside Drift"), IF(RawData!O10>50,"Upside Pressure","Downside Drift") ) ) -> Upside Drift | G10: =IF(RawData!J10="","", IF(RawData!J10<0,"Sell Into Close","Buy Into Close") ) -> Sell Into Close | H10: =IF(RawData!E10="","", IF(ABS(RawData!E10 - RawData!D10)/RawData!D10 < 0.02,"Near Call Wall","") ) -> #DIV/0! | I10: =IF(RawData!F10="","", IF(ABS(RawData!F10 - RawData!D10)/RawData!D10 < 0.02,"Near Put Wall","") ) -> #DIV/0! | J10: =IF(RawData!G10="","", IF(RawData!G10 < RawData!D10,"Below Flip","Above Flip") ) -> Above Flip | K10: =IF(RawData!H10="","", (IF(LE[[#This Row],[GammaRegime]]="Long Gamma",10,0)) + (IF(RawData!K10<0,10,0)) + (IF(AND(RawData!I10<0,RawData!O10>50),10,0)) + (IF(AND(RawData!I10>0,RawData!O10<50),10,0)) + (IF(ABS(RawData!E10 - RawData!D10)/RawData!D10 < 0.02,5,0)) + (IF(RawData!G10>RawData!D10,5,0)) + LE[[#This Row],[TierWeight]] ) -> #DIV/0! | L10: =IF(RawData!H10="","", (IF(LE[[#This Row],[GammaRegime]]="Short Gamma",10,0)) + (IF(RawData!K10>0,10,0)) + (IF(AND(RawData!I10>0,RawData!O10>50),10,0)) + (IF(AND(RawData!I10<0,RawData!O10<50),10,0)) + (IF(ABS(RawData!F10 - RawData!D10)/RawData!D10 < 0.02,5,0)) + (IF(RawData!G10<RawData!D10,5,0)) + LE[[#This Row],[TierWeight]] ) -> #DIV/0! | M10: =IF(LE[[#This Row],[BullScore]]>LE[[#This Row],[BearScore]],"Call", IF(LE[[#This Row],[BearScore]]>LE[[#This Row],[BullScore]],"Put","Avoid") ) -> #DIV/0! | N10: =MAX(LE[[#This Row],[BullScore]],LE[[#This Row],[BearScore]]) -> #DIV/0! | O10: =IF(LE[[#This Row],[GammaRegime]]="","", "Bias: " & LE[[#This Row],[TradeBias]] & " | Regime: " & LE[[#This Row],[GammaRegime]] & " | Delta: " & LE[[#This Row],[DeltaLean]] & " | Vanna: " & LE[[#This Row],[VannaBias]] & " | Charm: " & LE[[#This Row],[CharmBias]] & " | Flip: " & LE[[#This Row],[FlipFlag]] ) -> #DIV/0!
A11: =RawData!A11 -> GOOG | B11: =RawData!B11 -> 1 | C11: =IF(B11=1,10,IF(B11=2,5,0)) -> 10 | D11: =IF(RawData!H11="","", IF(RawData!H11>0,"Long Gamma","Short Gamma") ) -> Short Gamma | E11: =IF(RawData!K11="","", IF(RawData!K11>0,"Dealers Long (Sell Rips)","Dealers Short (Buy Rips)") ) | F11: =IF(OR(RawData!I11="",RawData!O11=""),"", IF(RawData!I11>0, IF(RawData!O11>50,"Downside Pressure","Upside Drift"), IF(RawData!O11>50,"Upside Pressure","Downside Drift") ) ) -> Upside Drift | G11: =IF(RawData!J11="","", IF(RawData!J11<0,"Sell Into Close","Buy Into Close") ) -> Sell Into Close | H11: =IF(RawData!E11="","", IF(ABS(RawData!E11 - RawData!D11)/RawData!D11 < 0.02,"Near Call Wall","") ) -> #DIV/0! | I11: =IF(RawData!F11="","", IF(ABS(RawData!F11 - RawData!D11)/RawData!D11 < 0.02,"Near Put Wall","") ) -> #DIV/0! | J11: =IF(RawData!G11="","", IF(RawData!G11 < RawData!D11,"Below Flip","Above Flip") ) -> Above Flip | K11: =IF(RawData!H11="","", (IF(LE[[#This Row],[GammaRegime]]="Long Gamma",10,0)) + (IF(RawData!K11<0,10,0)) + (IF(AND(RawData!I11<0,RawData!O11>50),10,0)) + (IF(AND(RawData!I11>0,RawData!O11<50),10,0)) + (IF(ABS(RawData!E11 - RawData!D11)/RawData!D11 < 0.02,5,0)) + (IF(RawData!G11>RawData!D11,5,0)) + LE[[#This Row],[TierWeight]] ) -> #DIV/0! | L11: =IF(RawData!H11="","", (IF(LE[[#This Row],[GammaRegime]]="Short Gamma",10,0)) + (IF(RawData!K11>0,10,0)) + (IF(AND(RawData!I11>0,RawData!O11>50),10,0)) + (IF(AND(RawData!I11<0,RawData!O11<50),10,0)) + (IF(ABS(RawData!F11 - RawData!D11)/RawData!D11 < 0.02,5,0)) + (IF(RawData!G11<RawData!D11,5,0)) + LE[[#This Row],[TierWeight]] ) -> #DIV/0! | M11: =IF(LE[[#This Row],[BullScore]]>LE[[#This Row],[BearScore]],"Call", IF(LE[[#This Row],[BearScore]]>LE[[#This Row],[BullScore]],"Put","Avoid") ) -> #DIV/0! | N11: =MAX(LE[[#This Row],[BullScore]],LE[[#This Row],[BearScore]]) -> #DIV/0! | O11: =IF(LE[[#This Row],[GammaRegime]]="","", "Bias: " & LE[[#This Row],[TradeBias]] & " | Regime: " & LE[[#This Row],[GammaRegime]] & " | Delta: " & LE[[#This Row],[DeltaLean]] & " | Vanna: " & LE[[#This Row],[VannaBias]] & " | Charm: " & LE[[#This Row],[CharmBias]] & " | Flip: " & LE[[#This Row],[FlipFlag]] ) -> #DIV/0!
A12: =RawData!A12 -> MSFT | B12: =RawData!B12 -> 1 | C12: =IF(B12=1,10,IF(B12=2,5,0)) -> 10 | D12: =IF(RawData!H12="","", IF(RawData!H12>0,"Long Gamma","Short Gamma") ) -> Long Gamma | E12: =IF(RawData!K12="","", IF(RawData!K12>0,"Dealers Long (Sell Rips)","Dealers Short (Buy Rips)") ) | F12: =IF(OR(RawData!I12="",RawData!O12=""),"", IF(RawData!I12>0, IF(RawData!O12>50,"Downside Pressure","Upside Drift"), IF(RawData!O12>50,"Upside Pressure","Downside Drift") ) ) -> Upside Drift | G12: =IF(RawData!J12="","", IF(RawData!J12<0,"Sell Into Close","Buy Into Close") ) -> Sell Into Close | H12: =IF(RawData!E12="","", IF(ABS(RawData!E12 - RawData!D12)/RawData!D12 < 0.02,"Near Call Wall","") ) -> #DIV/0! | I12: =IF(RawData!F12="","", IF(ABS(RawData!F12 - RawData!D12)/RawData!D12 < 0.02,"Near Put Wall","") ) -> #DIV/0! | J12: =IF(RawData!G12="","", IF(RawData!G12 < RawData!D12,"Below Flip","Above Flip") ) -> Above Flip | K12: =IF(RawData!H12="","", (IF(LE[[#This Row],[GammaRegime]]="Long Gamma",10,0)) + (IF(RawData!K12<0,10,0)) + (IF(AND(RawData!I12<0,RawData!O12>50),10,0)) + (IF(AND(RawData!I12>0,RawData!O12<50),10,0)) + (IF(ABS(RawData!E12 - RawData!D12)/RawData!D12 < 0.02,5,0)) + (IF(RawData!G12>RawData!D12,5,0)) + LE[[#This Row],[TierWeight]] ) -> #DIV/0! | L12: =IF(RawData!H12="","", (IF(LE[[#This Row],[GammaRegime]]="Short Gamma",10,0)) + (IF(RawData!K12>0,10,0)) + (IF(AND(RawData!I12>0,RawData!O12>50),10,0)) + (IF(AND(RawData!I12<0,RawData!O12<50),10,0)) + (IF(ABS(RawData!F12 - RawData!D12)/RawData!D12 < 0.02,5,0)) + (IF(RawData!G12<RawData!D12,5,0)) + LE[[#This Row],[TierWeight]] ) -> #DIV/0! | M12: =IF(LE[[#This Row],[BullScore]]>LE[[#This Row],[BearScore]],"Call", IF(LE[[#This Row],[BearScore]]>LE[[#This Row],[BullScore]],"Put","Avoid") ) -> #DIV/0! | N12: =MAX(LE[[#This Row],[BullScore]],LE[[#This Row],[BearScore]]) -> #DIV/0! | O12: =IF(LE[[#This Row],[GammaRegime]]="","", "Bias: " & LE[[#This Row],[TradeBias]] & " | Regime: " & LE[[#This Row],[GammaRegime]] & " | Delta: " & LE[[#This Row],[DeltaLean]] & " | Vanna: " & LE[[#This Row],[VannaBias]] & " | Charm: " & LE[[#This Row],[CharmBias]] & " | Flip: " & LE[[#This Row],[FlipFlag]] ) -> #DIV/0!
A13: =RawData!A13 -> NVDA | B13: =RawData!B13 -> 1 | C13: =IF(B13=1,10,IF(B13=2,5,0)) -> 10 | D13: =IF(RawData!H13="","", IF(RawData!H13>0,"Long Gamma","Short Gamma") ) -> Long Gamma | E13: =IF(RawData!K13="","", IF(RawData!K13>0,"Dealers Long (Sell Rips)","Dealers Short (Buy Rips)") ) | F13: =IF(OR(RawData!I13="",RawData!O13=""),"", IF(RawData!I13>0, IF(RawData!O13>50,"Downside Pressure","Upside Drift"), IF(RawData!O13>50,"Upside Pressure","Downside Drift") ) ) -> Upside Drift | G13: =IF(RawData!J13="","", IF(RawData!J13<0,"Sell Into Close","Buy Into Close") ) -> Sell Into Close | H13: =IF(RawData!E13="","", IF(ABS(RawData!E13 - RawData!D13)/RawData!D13 < 0.02,"Near Call Wall","") ) -> #DIV/0! | I13: =IF(RawData!F13="","", IF(ABS(RawData!F13 - RawData!D13)/RawData!D13 < 0.02,"Near Put Wall","") ) -> #DIV/0! | J13: =IF(RawData!G13="","", IF(RawData!G13 < RawData!D13,"Below Flip","Above Flip") ) -> Above Flip | K13: =IF(RawData!H13="","", (IF(LE[[#This Row],[GammaRegime]]="Long Gamma",10,0)) + (IF(RawData!K13<0,10,0)) + (IF(AND(RawData!I13<0,RawData!O13>50),10,0)) + (IF(AND(RawData!I13>0,RawData!O13<50),10,0)) + (IF(ABS(RawData!E13 - RawData!D13)/RawData!D13 < 0.02,5,0)) + (IF(RawData!G13>RawData!D13,5,0)) + LE[[#This Row],[TierWeight]] ) -> #DIV/0! | L13: =IF(RawData!H13="","", (IF(LE[[#This Row],[GammaRegime]]="Short Gamma",10,0)) + (IF(RawData!K13>0,10,0)) + (IF(AND(RawData!I13>0,RawData!O13>50),10,0)) + (IF(AND(RawData!I13<0,RawData!O13<50),10,0)) + (IF(ABS(RawData!F13 - RawData!D13)/RawData!D13 < 0.02,5,0)) + (IF(RawData!G13<RawData!D13,5,0)) + LE[[#This Row],[TierWeight]] ) -> #DIV/0! | M13: =IF(LE[[#This Row],[BullScore]]>LE[[#This Row],[BearScore]],"Call", IF(LE[[#This Row],[BearScore]]>LE[[#This Row],[BullScore]],"Put","Avoid") ) -> #DIV/0! | N13: =MAX(LE[[#This Row],[BullScore]],LE[[#This Row],[BearScore]]) -> #DIV/0! | O13: =IF(LE[[#This Row],[GammaRegime]]="","", "Bias: " & LE[[#This Row],[TradeBias]] & " | Regime: " & LE[[#This Row],[GammaRegime]] & " | Delta: " & LE[[#This Row],[DeltaLean]] & " | Vanna: " & LE[[#This Row],[VannaBias]] & " | Charm: " & LE[[#This Row],[CharmBias]] & " | Flip: " & LE[[#This Row],[FlipFlag]] ) -> #DIV/0!
... A60: =RawData!A60 -> XLF | B60: =RawData!B60 -> 1 | C60: =IF(B60=1,10,IF(B60=2,5,0)) -> 10 | D60: =IF(RawData!H60="","", IF(RawData!H60>0,"Long Gamma","Short Gamma") ) -> Short Gamma | E60: =IF(RawData!K60="","", IF(RawData!K60>0,"Dealers Long (Sell Rips)","Dealers Short (Buy Rips)") ) | F60: =IF(OR(RawData!I60="",RawData!O60=""),"", IF(RawData!I60>0, IF(RawData!O60>50,"Downside Pressure","Upside Drift"), IF(RawData!O60>50,"Upside Pressure","Downside Drift") ) ) -> Upside Drift | G60: =IF(RawData!J60="","", IF(RawData!J60<0,"Sell Into Close","Buy Into Close") ) -> Sell Into Close | H60: =IF(RawData!E60="","", IF(ABS(RawData!E60 - RawData!D60)/RawData!D60 < 0.02,"Near Call Wall","") ) -> #DIV/0! | I60: =IF(RawData!F60="","", IF(ABS(RawData!F60 - RawData!D60)/RawData!D60 < 0.02,"Near Put Wall","") ) -> #DIV/0! | J60: =IF(RawData!G60="","", IF(RawData!G60 < RawData!D60,"Below Flip","Above Flip") ) -> Above Flip | K60: =IF(RawData!H60="","", (IF(LE[[#This Row],[GammaRegime]]="Long Gamma",10,0)) + (IF(RawData!K60<0,10,0)) + (IF(AND(RawData!I60<0,RawData!O60>50),10,0)) + (IF(AND(RawData!I60>0,RawData!O60<50),10,0)) + (IF(ABS(RawData!E60 - RawData!D60)/RawData!D60 < 0.02,5,0)) + (IF(RawData!G60>RawData!D60,5,0)) + LE[[#This Row],[TierWeight]] ) -> #DIV/0! | L60: =IF(RawData!H60="","", (IF(LE[[#This Row],[GammaRegime]]="Short Gamma",10,0)) + (IF(RawData!K60>0,10,0)) + (IF(AND(RawData!I60>0,RawData!O60>50),10,0)) + (IF(AND(RawData!I60<0,RawData!O60<50),10,0)) + (IF(ABS(RawData!F60 - RawData!D60)/RawData!D60 < 0.02,5,0)) + (IF(RawData!G60<RawData!D60,5,0)) + LE[[#This Row],[TierWeight]] ) -> #DIV/0! | M60: =IF(LE[[#This Row],[BullScore]]>LE[[#This Row],[BearScore]],"Call", IF(LE[[#This Row],[BearScore]]>LE[[#This Row],[BullScore]],"Put","Avoid") ) -> #DIV/0! | N60: =MAX(LE[[#This Row],[BullScore]],LE[[#This Row],[BearScore]]) -> #DIV/0! | O60: =IF(LE[[#This Row],[GammaRegime]]="","", "Bias: " & LE[[#This Row],[TradeBias]] & " | Regime: " & LE[[#This Row],[GammaRegime]] & " | Delta: " & LE[[#This Row],[DeltaLean]] & " | Vanna: " & LE[[#This Row],[VannaBias]] & " | Charm: " & LE[[#This Row],[CharmBias]] & " | Flip: " & LE[[#This Row],[FlipFlag]] ) -> #DIV/0!
A61: =RawData!#REF! -> #REF! | B61: =RawData!#REF! -> #REF! | C61: =IF(B61=1,10,IF(B61=2,5,0)) -> #REF! | D61: =IF(RawData!#REF!="","", IF(RawData!#REF!>0,"Long Gamma","Short Gamma") ) -> #REF! | E61: =IF(RawData!#REF!="","", IF(RawData!#REF!>0,"Dealers Long (Sell Rips)","Dealers Short (Buy Rips)") ) -> #REF! | F61: =IF(OR(RawData!#REF!="",RawData!#REF!=""),"", IF(RawData!#REF!>0, IF(RawData!#REF!>50,"Downside Pressure","Upside Drift"), IF(RawData!#REF!>50,"Upside Pressure","Downside Drift") ) ) -> #REF! | G61: =IF(RawData!#REF!="","", IF(RawData!#REF!<0,"Sell Into Close","Buy Into Close") ) -> #REF! | H61: =IF(RawData!#REF!="","", IF(ABS(RawData!#REF! - RawData!#REF!)/RawData!#REF! < 0.02,"Near Call Wall","") ) -> #REF! | I61: =IF(RawData!#REF!="","", IF(ABS(RawData!#REF! - RawData!#REF!)/RawData!#REF! < 0.02,"Near Put Wall","") ) -> #REF! | J61: =IF(RawData!#REF!="","", IF(RawData!#REF! < RawData!#REF!,"Below Flip","Above Flip") ) -> #REF! | K61: =IF(RawData!#REF!="","", (IF(LE[[#This Row],[GammaRegime]]="Long Gamma",10,0)) + (IF(RawData!#REF!<0,10,0)) + (IF(AND(RawData!#REF!<0,RawData!#REF!>50),10,0)) + (IF(AND(RawData!#REF!>0,RawData!#REF!<50),10,0)) + (IF(ABS(RawData!#REF! - RawData!#REF!)/RawData!#REF! < 0.02,5,0)) + (IF(RawData!#REF!>RawData!#REF!,5,0)) + LE[[#This Row],[TierWeight]] ) -> #REF! | L61: =IF(RawData!#REF!="","", (IF(LE[[#This Row],[GammaRegime]]="Short Gamma",10,0)) + (IF(RawData!#REF!>0,10,0)) + (IF(AND(RawData!#REF!>0,RawData!#REF!>50),10,0)) + (IF(AND(RawData!#REF!<0,RawData!#REF!<50),10,0)) + (IF(ABS(RawData!#REF! - RawData!#REF!)/RawData!#REF! < 0.02,5,0)) + (IF(RawData!#REF!<RawData!#REF!,5,0)) + LE[[#This Row],[TierWeight]] ) -> #REF! | M61: =IF(LE[[#This Row],[BullScore]]>LE[[#This Row],[BearScore]],"Call", IF(LE[[#This Row],[BearScore]]>LE[[#This Row],[BullScore]],"Put","Avoid") ) -> #REF! | N61: =MAX(LE[[#This Row],[BullScore]],LE[[#This Row],[BearScore]]) -> #REF! | O61: =IF(LE[[#This Row],[GammaRegime]]="","", "Bias: " & LE[[#This Row],[TradeBias]] & " | Regime: " & LE[[#This Row],[GammaRegime]] & " | Delta: " & LE[[#This Row],[DeltaLean]] & " | Vanna: " & LE[[#This Row],[VannaBias]] & " | Charm: " & LE[[#This Row],[CharmBias]] & " | Flip: " & LE[[#This Row],[FlipFlag]] ) -> #REF!
A62: =RawData!#REF! -> #REF! | B62: =RawData!#REF! -> #REF! | C62: =IF(B62=1,10,IF(B62=2,5,0)) -> #REF! | D62: =IF(RawData!#REF!="","", IF(RawData!#REF!>0,"Long Gamma","Short Gamma") ) -> #REF! | E62: =IF(RawData!#REF!="","", IF(RawData!#REF!>0,"Dealers Long (Sell Rips)","Dealers Short (Buy Rips)") ) -> #REF! | F62: =IF(OR(RawData!#REF!="",RawData!#REF!=""),"", IF(RawData!#REF!>0, IF(RawData!#REF!>50,"Downside Pressure","Upside Drift"), IF(RawData!#REF!>50,"Upside Pressure","Downside Drift") ) ) -> #REF! | G62: =IF(RawData!#REF!="","", IF(RawData!#REF!<0,"Sell Into Close","Buy Into Close") ) -> #REF! | H62: =IF(RawData!#REF!="","", IF(ABS(RawData!#REF! - RawData!#REF!)/RawData!#REF! < 0.02,"Near Call Wall","") ) -> #REF! | I62: =IF(RawData!#REF!="","", IF(ABS(RawData!#REF! - RawData!#REF!)/RawData!#REF! < 0.02,"Near Put Wall","") ) -> #REF! | J62: =IF(RawData!#REF!="","", IF(RawData!#REF! < RawData!#REF!,"Below Flip","Above Flip") ) -> #REF! | K62: =IF(RawData!#REF!="","", (IF(LE[[#This Row],[GammaRegime]]="Long Gamma",10,0)) + (IF(RawData!#REF!<0,10,0)) + (IF(AND(RawData!#REF!<0,RawData!#REF!>50),10,0)) + (IF(AND(RawData!#REF!>0,RawData!#REF!<50),10,0)) + (IF(ABS(RawData!#REF! - RawData!#REF!)/RawData!#REF! < 0.02,5,0)) + (IF(RawData!#REF!>RawData!#REF!,5,0)) + LE[[#This Row],[TierWeight]] ) -> #REF! | L62: =IF(RawData!#REF!="","", (IF(LE[[#This Row],[GammaRegime]]="Short Gamma",10,0)) + (IF(RawData!#REF!>0,10,0)) + (IF(AND(RawData!#REF!>0,RawData!#REF!>50),10,0)) + (IF(AND(RawData!#REF!<0,RawData!#REF!<50),10,0)) + (IF(ABS(RawData!#REF! - RawData!#REF!)/RawData!#REF! < 0.02,5,0)) + (IF(RawData!#REF!<RawData!#REF!,5,0)) + LE[[#This Row],[TierWeight]] ) -> #REF! | M62: =IF(LE[[#This Row],[BullScore]]>LE[[#This Row],[BearScore]],"Call", IF(LE[[#This Row],[BearScore]]>LE[[#This Row],[BullScore]],"Put","Avoid") ) -> #REF! | N62: =MAX(LE[[#This Row],[BullScore]],LE[[#This Row],[BearScore]]) -> #REF! | O62: =IF(LE[[#This Row],[GammaRegime]]="","", "Bias: " & LE[[#This Row],[TradeBias]] & " | Regime: " & LE[[#This Row],[GammaRegime]] & " | Delta: " & LE[[#This Row],[DeltaLean]] & " | Vanna: " & LE[[#This Row],[VannaBias]] & " | Charm: " & LE[[#This Row],[CharmBias]] & " | Flip: " & LE[[#This Row],[FlipFlag]] ) -> #REF!
A63: =RawData!A61 -> XLK | B63: =RawData!B61 -> 1 | C63: =IF(B63=1,10,IF(B63=2,5,0)) -> 10 | D63: =IF(RawData!H61="","", IF(RawData!H61>0,"Long Gamma","Short Gamma") ) -> Short Gamma | E63: =IF(RawData!K61="","", IF(RawData!K61>0,"Dealers Long (Sell Rips)","Dealers Short (Buy Rips)") ) | F63: =IF(OR(RawData!I61="",RawData!O61=""),"", IF(RawData!I61>0, IF(RawData!O61>50,"Downside Pressure","Upside Drift"), IF(RawData!O61>50,"Upside Pressure","Downside Drift") ) ) -> Downside Pressure | G63: =IF(RawData!J61="","", IF(RawData!J61<0,"Sell Into Close","Buy Into Close") ) -> Sell Into Close | H63: =IF(RawData!E61="","", IF(ABS(RawData!E61 - RawData!D61)/RawData!D61 < 0.02,"Near Call Wall","") ) -> #DIV/0! | I63: =IF(RawData!F61="","", IF(ABS(RawData!F61 - RawData!D61)/RawData!D61 < 0.02,"Near Put Wall","") ) -> #DIV/0! | J63: =IF(RawData!G61="","", IF(RawData!G61 < RawData!D61,"Below Flip","Above Flip") ) -> Above Flip | K63: =IF(RawData!H61="","", (IF(LE[[#This Row],[GammaRegime]]="Long Gamma",10,0)) + (IF(RawData!K61<0,10,0)) + (IF(AND(RawData!I61<0,RawData!O61>50),10,0)) + (IF(AND(RawData!I61>0,RawData!O61<50),10,0)) + (IF(ABS(RawData!E61 - RawData!D61)/RawData!D61 < 0.02,5,0)) + (IF(RawData!G61>RawData!D61,5,0)) + LE[[#This Row],[TierWeight]] ) -> #DIV/0! | L63: =IF(RawData!H61="","", (IF(LE[[#This Row],[GammaRegime]]="Short Gamma",10,0)) + (IF(RawData!K61>0,10,0)) + (IF(AND(RawData!I61>0,RawData!O61>50),10,0)) + (IF(AND(RawData!I61<0,RawData!O61<50),10,0)) + (IF(ABS(RawData!F61 - RawData!D61)/RawData!D61 < 0.02,5,0)) + (IF(RawData!G61<RawData!D61,5,0)) + LE[[#This Row],[TierWeight]] ) -> #DIV/0! | M63: =IF(LE[[#This Row],[BullScore]]>LE[[#This Row],[BearScore]],"Call", IF(LE[[#This Row],[BearScore]]>LE[[#This Row],[BullScore]],"Put","Avoid") ) -> #DIV/0! | N63: =MAX(LE[[#This Row],[BullScore]],LE[[#This Row],[BearScore]]) -> #DIV/0! | O63: =IF(LE[[#This Row],[GammaRegime]]="","", "Bias: " & LE[[#This Row],[TradeBias]] & " | Regime: " & LE[[#This Row],[GammaRegime]] & " | Delta: " & LE[[#This Row],[DeltaLean]] & " | Vanna: " & LE[[#This Row],[VannaBias]] & " | Charm: " & LE[[#This Row],[CharmBias]] & " | Flip: " & LE[[#This Row],[FlipFlag]] ) -> #DIV/0!

Sheet Dashboard
A1: Ticker | B1: GammaRegime | C1: DeltaLean | D1: VannaBias | E1: CharmBias | F1: Conviction | G1: Notes | J1: Ticker | K1: GammaRegime | L1: DeltaLean | M1: VannaBias | N1: CharmBias | O1: Conviction | P1: Notes
A2: {=_xlfn._xlws.SORT( _xlfn._xlws.FILTER( LE[[Ticker]:[Conviction]], (LE[TradeBias]="Call")*(LE[Conviction]>=60) ), 4, FALSE )} -> #DIV/0! | J2: {=_xlfn._xlws.SORT( _xlfn._xlws.FILTER( LE[[Ticker]:[Conviction]], (LE[TradeBias]="Put")*(LE[Conviction]>=60) ), 4, FALSE )} -> #DIV/0!
A3: {=_xlfn._xlws.SORT( _xlfn._xlws.FILTER( LE[[Ticker]:[Conviction]], (LE[TradeBias]="Call")*(LE[Conviction]>=60) ), 4, FALSE )} -> #DIV/0! | J3: {=_xlfn._xlws.SORT( _xlfn._xlws.FILTER( LE[[Ticker]:[Conviction]], (LE[TradeBias]="Put")*(LE[Conviction]>=60) ), 4, FALSE )} -> #DIV/0!
A4: {=_xlfn._xlws.SORT( _xlfn._xlws.FILTER( LE[[Ticker]:[Conviction]], (LE[TradeBias]="Call")*(LE[Conviction]>=60) ), 4, FALSE )} -> #DIV/0! | J4: {=_xlfn._xlws.SORT( _xlfn._xlws.FILTER( LE[[Ticker]:[Conviction]], (LE[TradeBias]="Put")*(LE[Conviction]>=60) ), 4, FALSE )} -> #DIV/0!
A5: {=_xlfn._xlws.SORT( _xlfn._xlws.FILTER( LE[[Ticker]:[Conviction]], (LE[TradeBias]="Call")*(LE[Conviction]>=60) ), 4, FALSE )} -> #DIV/0! | J5: {=_xlfn._xlws.SORT( _xlfn._xlws.FILTER( LE[[Ticker]:[Conviction]], (LE[TradeBias]="Put")*(LE[Conviction]>=60) ), 4, FALSE )} -> #DIV/0!
A6: {=_xlfn._xlws.SORT( _xlfn._xlws.FILTER( LE[[Ticker]:[Conviction]], (LE[TradeBias]="Call")*(LE[Conviction]>=60) ), 4, FALSE )} -> #DIV/0! | J6: {=_xlfn._xlws.SORT( _xlfn._xlws.FILTER( LE[[Ticker]:[Conviction]], (LE[TradeBias]="Put")*(LE[Conviction]>=60) ), 4, FALSE )} -> #DIV/0!
A7: {=_xlfn._xlws.SORT( _xlfn._xlws.FILTER( LE[[Ticker]:[Conviction]], (LE[TradeBias]="Call")*(LE[Conviction]>=60) ), 4, FALSE )} -> #DIV/0! | J7: {=_xlfn._xlws.SORT( _xlfn._xlws.FILTER( LE[[Ticker]:[Conviction]], (LE[TradeBias]="Put")*(LE[Conviction]>=60) ), 4, FALSE )} -> #DIV/0!
A8: {=_xlfn._xlws.SORT( _xlfn._xlws.FILTER( LE[[Ticker]:[Conviction]], (LE[TradeBias]="Call")*(LE[Conviction]>=60) ), 4, FALSE )} -> #DIV/0! | J8: {=_xlfn._xlws.SORT( _xlfn._xlws.FILTER( LE[[Ticker]:[Conviction]], (LE[TradeBias]="Put")*(LE[Conviction]>=60) ), 4, FALSE )} -> #DIV/0!
A9: {=_xlfn._xlws.SORT( _xlfn._xlws.FILTER( LE[[Ticker]:[Conviction]], (LE[TradeBias]="Call")*(LE[Conviction]>=60) ), 4, FALSE )} -> #DIV/0! | J9: {=_xlfn._xlws.SORT( _xlfn._xlws.FILTER( LE[[Ticker]:[Conviction]], (LE[TradeBias]="Put")*(LE[Conviction]>=60) ), 4, FALSE )} -> #DIV/0!
A10: {=_xlfn._xlws.SORT( _xlfn._xlws.FILTER( LE[[Ticker]:[Conviction]], (LE[TradeBias]="Call")*(LE[Conviction]>=60) ), 4, FALSE )} -> #DIV/0! | J10: {=_xlfn._xlws.SORT( _xlfn._xlws.FILTER( LE[[Ticker]:[Conviction]], (LE[TradeBias]="Put")*(LE[Conviction]>=60) ), 4, FALSE )} -> #DIV/0!
A11: {=_xlfn._xlws.SORT( _xlfn._xlws.FILTER( LE[[Ticker]:[Conviction]], (LE[TradeBias]="Call")*(LE[Conviction]>=60) ), 4, FALSE )} -> #DIV/0! | J11: {=_xlfn._xlws.SORT( _xlfn._xlws.FILTER( LE[[Ticker]:[Conviction]], (LE[TradeBias]="Put")*(LE[Conviction]>=60) ), 4, FALSE )} -> #DIV/0!
A14: Ticker | B14: GammaRegime | C14: NetGamma | D14: DeltaLean | E14: VannaBias | F14: Notes | J14: Ticker | K14: GammaRegime | L14: DeltaLean | M14: VannaBias | N14: CharmBias | O14: Conviction | P14: Notes
A15: {=_xlfn.TAKE(_xlfn.SORTBY( LE[[Ticker]:[GammaRegime]], ABS(RawData!D:D), -1 ), 10)} -> #VALUE! | J15: {=_xlfn._xlws.SORT( _xlfn._xlws.FILTER( LE[[Ticker]:[Notes]], (LE[CallWallFlag]<>"") + (LE[PutWallFlag]<>"") ), 6, FALSE )} -> #DIV/0!
A16: {=_xlfn.TAKE(_xlfn.SORTBY( LE[[Ticker]:[GammaRegime]], ABS(RawData!D:D), -1 ), 10)} -> #VALUE! | J16: {=_xlfn._xlws.SORT( _xlfn._xlws.FILTER( LE[[Ticker]:[Notes]], (LE[CallWallFlag]<>"") + (LE[PutWallFlag]<>"") ), 6, FALSE )} -> #DIV/0!
A17: {=_xlfn.TAKE(_xlfn.SORTBY( LE[[Ticker]:[GammaRegime]], ABS(RawData!D:D), -1 ), 10)} -> #VALUE! | J17: {=_xlfn._xlws.SORT( _xlfn._xlws.FILTER( LE[[Ticker]:[Notes]], (LE[CallWallFlag]<>"") + (LE[PutWallFlag]<>"") ), 6, FALSE )} -> #DIV/0!
A18: {=_xlfn.TAKE(_xlfn.SORTBY( LE[[Ticker]:[GammaRegime]], ABS(RawData!D:D), -1 ), 10)} -> #VALUE! | J18: {=_xlfn._xlws.SORT( _xlfn._xlws.FILTER( LE[[Ticker]:[Notes]], (LE[CallWallFlag]<>"") + (LE[PutWallFlag]<>"") ), 6, FALSE )} -> #DIV/0!
A19: {=_xlfn.TAKE(_xlfn.SORTBY( LE[[Ticker]:[GammaRegime]], ABS(RawData!D:D), -1 ), 10)} -> #VALUE! | J19: {=_xlfn._xlws.SORT( _xlfn._xlws.FILTER( LE[[Ticker]:[Notes]], (LE[CallWallFlag]<>"") + (LE[PutWallFlag]<>"") ), 6, FALSE )} -> #DIV/0!
A20: {=_xlfn.TAKE(_xlfn.SORTBY( LE[[Ticker]:[GammaRegime]], ABS(RawData!D:D), -1 ), 10)} -> #VALUE! | J20: {=_xlfn._xlws.SORT( _xlfn._xlws.FILTER( LE[[Ticker]:[Notes]], (LE[CallWallFlag]<>"") + (LE[PutWallFlag]<>"") ), 6, FALSE )} -> #DIV/0!
A21: {=_xlfn.TAKE(_xlfn.SORTBY( LE[[Ticker]:[GammaRegime]], ABS(RawData!D:D), -1 ), 10)} -> #VALUE!
A22: {=_xlfn.TAKE(_xlfn.SORTBY( LE[[Ticker]:[GammaRegime]], ABS(RawData!D:D), -1 ), 10)} -> #VALUE!
A23: {=_xlfn.TAKE(_xlfn.SORTBY( LE[[Ticker]:[GammaRegime]], ABS(RawData!D:D), -1 ), 10)} -> #VALUE!
A24: {=_xlfn.TAKE(_xlfn.SORTBY( LE[[Ticker]:[GammaRegime]], ABS(RawData!D:D), -1 ), 10)} -> #VALUE!
A27: Ticker | B27: GammaRegime | C27: DeltaLean | D27: VannaBias | E27: CharmBias | F27: Conviction | G27: FlipFlag | H27: Notes | J27: Ticker | K27: GammaRegime | L27: DeltaLean | M27: VannaBias | N27: CharmBias | O27: Conviction | P27: Notes
A28: {=_xlfn._xlws.SORT( _xlfn._xlws.FILTER( LE[[Ticker]:[Notes]], LE[FlipFlag]<>"" ), 6, FALSE )} -> #REF! | J28: {=_xlfn._xlws.SORT( _xlfn._xlws.FILTER( LE[[Ticker]:[Notes]], (LE[CharmBias]="Buy Into Close") + (LE[CharmBias]="Sell Into Close") ), 6, FALSE )} -> #REF!
A29: {=_xlfn._xlws.SORT( _xlfn._xlws.FILTER( LE[[Ticker]:[Notes]], LE[FlipFlag]<>"" ), 6, FALSE )} -> #REF! | J29: {=_xlfn._xlws.SORT( _xlfn._xlws.FILTER( LE[[Ticker]:[Notes]], (LE[CharmBias]="Buy Into Close") + (LE[CharmBias]="Sell Into Close") ), 6, FALSE )} -> #REF!
A30: {=_xlfn._xlws.SORT( _xlfn._xlws.FILTER( LE[[Ticker]:[Notes]], LE[FlipFlag]<>"" ), 6, FALSE )} -> #REF! | J30: {=_xlfn._xlws.SORT( _xlfn._xlws.FILTER( LE[[Ticker]:[Notes]], (LE[CharmBias]="Buy Into Close") + (LE[CharmBias]="Sell Into Close") ), 6, FALSE )} -> #REF!
A31: {=_xlfn._xlws.SORT( _xlfn._xlws.FILTER( LE[[Ticker]:[Notes]], LE[FlipFlag]<>"" ), 6, FALSE )} -> #REF! | J31: {=_xlfn._xlws.SORT( _xlfn._xlws.FILTER( LE[[Ticker]:[Notes]], (LE[CharmBias]="Buy Into Close") + (LE[CharmBias]="Sell Into Close") ), 6, FALSE )} -> #REF!
A32: {=_xlfn._xlws.SORT( _xlfn._xlws.FILTER( LE[[Ticker]:[Notes]], LE[FlipFlag]<>"" ), 6, FALSE )} -> #REF! | J32: {=_xlfn._xlws.SORT( _xlfn._xlws.FILTER( LE[[Ticker]:[Notes]], (LE[CharmBias]="Buy Into Close") + (LE[CharmBias]="Sell Into Close") ), 6, FALSE )} -> #REF!
A33: {=_xlfn._xlws.SORT( _xlfn._xlws.FILTER( LE[[Ticker]:[Notes]], LE[FlipFlag]<>"" ), 6, FALSE )} -> #REF! | J33: {=_xlfn._xlws.SORT( _xlfn._xlws.FILTER( LE[[Ticker]:[Notes]], (LE[CharmBias]="Buy Into Close") + (LE[CharmBias]="Sell Into Close") ), 6, FALSE )} -> #REF!
A56: Ticker | B56: GammaRegime | C56: DeltaLean | D56: VannaBias | E56: CharmBias | F56: Conviction | G56: Notes
A57: {=_xlfn._xlws.SORT( _xlfn._xlws.FILTER( LE[[Ticker]:[Notes]], (LE[CharmBias]="Buy Into Close") + (LE[CharmBias]="Sell Into Close") ), 6, FALSE )} -> #REF!
